<?xml version="1.0"?>
<robot name="box">
    <link name="world" />
    <link name="box">
        <inertial>
            <mass value="10.0" />
            <origin xyz="0 0 0" rpy="0 0 0" />
            <inertia ixx="1.0" ixy="0" ixz="0" iyy="1.0" iyz="0" izz="1.0" />
        </inertial>
        <visual>
            <origin xyz="0 0 0" rpy="0 0 0" />
            <geometry>
                <box size="0.1 0.1 0.1 " />
            </geometry>
            <material name="Cyan">
                <color rgba="0 1.0 1.0 1.0"/>
            </material>
        </visual>
        <collision group="default">
            <origin xyz="0 0 0" rpy="0 0 0" />
            <geometry>
                <box size="0.1 0.1 0.1" />
            </geometry>
        </collision>
    </link>
    <joint name="world_joint" type="floating">
        <origin xyz="0 0 1" rpy="0 0 0" />
        <parent link="world" />
        <child link="box" />
    </joint>
</robot>
